<?xml version="1.0"?>
<robot xmlns:xacro="http://www.ros.org/wiki/xacro">
    <xacro:macro name="rotating_arm_part" params="side parent reflect">
    <joint name="${side}_slider_joint" type="prismatic">
        <origin xyz="${reflect * 0.25} 0 0.1" rpy="0 0 0"/>
        <parent link="${parent}"/>
        <child link="${side}_slider_link"/>
        <axis xyz="0 1 0"/>
        <limit upper="2" lower="0" effort="100.0" velocity="10.0"/>
    </joint>

    <link name="${side}_slider_link">
        <visual>
            <origin xyz="0 0 0.05" rpy="0 0 0"/>
            <geometry>
                <box size="0.2 0.4 0.1"/>
            </geometry>
            <material name="blue">
                <color rgba="0 0 1 0.5"/>
            </material>
        </visual>
        <collision>
            <origin xyz="0 0 0.05" rpy="0 0 0"/>
            <geometry>
                <box size="0.2 0.4 0.1"/>
            </geometry>
        </collision>
        <inertial>
            <origin xyz="0 0 0.05" rpy="0 0 0"/>
            <mass value="0.5"/>
            <inertia ixx="0.007083" ixy="0.0" ixz="0.0" iyy="0.0020833" iyz="0.0" izz="0.008333"/>
        </inertial>
    </link>

    <joint name="${side}_rotating_arm_joint" type="revolute">
        <origin xyz="${reflect * 0.25} 0 0.1" rpy="0 ${pi/2} 0"/>
        <parent link="${side}_slider_link"/>
        <child link="${side}_rotating_arm_link"/>
        <axis xyz="0 0 1"/>
        <limit effort="100.0" upper="${pi/2}" lower="${-pi/2}" velocity="${pi/4}"/>
    </joint>

    <link name="${side}_rotating_arm_link">
        <visual>
            <origin xyz="0 0 0" rpy="0 0 0"/>
            <geometry>
                <cylinder radius="0.05" length="0.5"/>
            </geometry>
            <material name="white">
                <color rgba="1 1 1 0.5"/>
            </material>
        </visual>
        <collision>
            <origin xyz="0 0 0" rpy="0 0 0"/>
            <geometry>
                <cylinder radius="0.05" length="0.5"/>
            </geometry>
        </collision>
        <inertial>
            <origin xyz="0 0 0" rpy="0 0 0"/>
            <mass value="0.5"/>
            <inertia ixx="0.01073" ixy="0.0" ixz="0.0" iyy="0.01073" iyz="0.0" izz="0.000625"/>
        </inertial>
    </link>

    <joint name="${side}_gripper_arm_support_joint" type="fixed">
        <origin xyz="0 0 ${reflect * 0.25}" rpy="0 -${pi/2} 0"/>
        <parent link="${side}_rotating_arm_link"/>
        <child link="${side}_gripper_arm_support_link"/>
    </joint>

    <link name="${side}_gripper_arm_support_link">
        <visual>
            <origin xyz="0 0 0.1" rpy="0 0 0"/>
            <geometry>
                <cylinder radius="0.05" length="0.2"/>
            </geometry>
            <material name="purple">
                <color rgba="1 0 1 0.5"/>
            </material>
        </visual>
        <collision>
            <origin xyz="0 0 0.1" rpy="0 0 0"/>
            <geometry>
                <cylinder radius="0.05" length="0.2"/>
            </geometry>
        </collision>
        <inertial>
            <origin xyz="0 0 0.1" rpy="0 0 0"/>
            <mass value="0.2"/>
            <inertia ixx="0.001979" ixy="0.0" ixz="0.0" iyy="0.001979" iyz="0.0" izz="0.001"/>
        </inertial>
    </link>
    </xacro:macro>
</robot>

