<?xml version="1.0"?>
<robot xmlns:xacro="http://www.ros.org/wiki/xacro" name="robot">
    <link name="world"/>

    <joint name="base_joint" type="fixed">
        <parent link="world"/>
        <child link="base_link"/>
        <origin xyz="1.5 0.5 0.1"/>
    </joint>

    <link name="base_link">
        <visual>
            <origin xyz="0 1 0" rpy="0 0 0"/>
            <geometry>
                <box size="0.5 2 0.2"/>
            </geometry>
        </visual>
        <collision>
            <origin xyz="0 1 0" rpy="0 0 0"/>
            <geometry>
                <box size="0.5 2 0.2"/>
            </geometry>
        </collision>
        <inertial>
            <origin xyz="0 1 0" rpy="0 0 0"/>
            <mass value="2"/>
            <inertia ixx="0.6733" ixy="0.0" ixz="0.0" iyy="0.04833" iyz="0.0" izz="0.7083"/>
        </inertial>
    </link>

    <joint name="left_slider_joint" type="prismatic">
        <origin xyz="0.25 0 0.1" rpy="0 0 0"/>
        <parent link="base_link"/>
        <child link="left_slider_link"/>
        <axis xyz="0 1 0"/>
        <limit upper="2" lower="0" effort="100.0" velocity="10.0"/>
    </joint>

    <link name="left_slider_link">
        <visual>
            <origin xyz="0 0 0.05" rpy="0 0 0"/>
            <geometry>
                <box size="0.2 0.4 0.1"/>
            </geometry>
            <material name="blue">
                <color rgba="0 0 1 0.5"/>
            </material>
        </visual>
        <collision>
            <origin xyz="0 0 0.05" rpy="0 0 0"/>
            <geometry>
                <box size="0.2 0.4 0.1"/>
            </geometry>
        </collision>
        <inertial>
            <origin xyz="0 0 0.05" rpy="0 0 0"/>
            <mass value="0.5"/>
            <inertia ixx="0.007083" ixy="0.0" ixz="0.0" iyy="0.0020833" iyz="0.0" izz="0.008333"/>
        </inertial>
    </link>
</robot>

